<?xml version="1.0"?>
<!-- created with Phobos 1.0.1 "Capricious Choutengan" -->
  <robot name="target_robot">

    <link name="base_link">
      <inertial>
        <origin xyz="0 0 0" rpy="0 0 0"/>
        <mass value="0.001"/>
        <inertia ixx="0.001" ixy="0" ixz="0" iyy="0.001" iyz="0" izz="0.001"/>
      </inertial>
      <visual name="base">
        <origin xyz="-0.00344 0.04636 0" rpy="1.5708 0 0"/>
        <geometry>
          <mesh filename="../meshes/dae/base_link.dae" scale="0.001 0.001 0.001"/>
        </geometry>
      </visual>
      <collision name="base">
        <origin xyz="0 -2e-05 -0.03168" rpy="1.5708 0 0"/>
        <geometry>
          <box size="0.5 0.28033 0.595"/>
        </geometry>
      </collision>
    </link>

    <link name="turret_pitch_link">
      <inertial>
        <origin xyz="0 0 0" rpy="0 0 0"/>
        <mass value="0.001"/>
        <inertia ixx="0.001" ixy="0" ixz="0" iyy="0.001" iyz="0" izz="0.001"/>
      </inertial>
      <visual name="turret_pitch">
        <origin xyz="0.02853 -0.05461 0.05365" rpy="0 1.5708 0"/>
        <geometry>
          <mesh filename="../meshes/dae/turret_pitch.dae" scale="0.001 0.001 0.001"/>
        </geometry>
      </visual>
      <collision name="turret_pitch">
        <origin xyz="0.06629 -0.05478 0.06775" rpy="0 1.5708 0"/>
        <geometry>
          <box size="0.10594 0.12283 0.28648"/>
        </geometry>
      </collision>
    </link>

    <link name="turret_yaw_link">
      <inertial>
        <origin xyz="0 0 0" rpy="0 0 0"/>
        <mass value="0.001"/>
        <inertia ixx="0.001" ixy="0" ixz="0" iyy="0.001" iyz="0" izz="0.001"/>
      </inertial>
      <visual name="turret_yaw">
        <origin xyz="0 0 0" rpy="1.5708 0 0"/>
        <geometry>
          <mesh filename="../meshes/dae/turret_yaw.dae" scale="0.001 0.001 0.001"/>
        </geometry>
      </visual>
      <collision name="turret_yaw">
        <origin xyz="-0.01409 0.00635 -0.01969" rpy="1.5708 0 0"/>
        <geometry>
          <box size="0.24047 0.21628 0.39979"/>
        </geometry>
      </collision>
    </link>

    <joint name="turret_pitch_joint" type="revolute">
      <origin xyz="0.05365 0.02853 0.05461" rpy="1.5708 0 -1.5708"/>
      <parent link="turret_yaw_link"/>
      <child link="turret_pitch_link"/>
      <axis xyz="0 0 1.0"/>
      <limit lower="-1.04" upper="1.04" effort="5.0" velocity="1.0"/>
    </joint>

    <joint name="turret_yaw_joint" type="revolute">
      <origin xyz="0.01434 -0.02883 0.18781" rpy="0 0 0"/>
      <parent link="base_link"/>
      <child link="turret_yaw_link"/>
      <axis xyz="0 0 1.0"/>
      <limit lower="-3.14" upper="3.14" effort="5.0" velocity="1.0"/>
    </joint>

     <gazebo>
       <plugin name="object_controller" filename="libgazebo_ros_planar_move.so">
         <commandTopic>/icra_robot/cmd_vel</commandTopic>
         <odometryTopic>odom</odometryTopic>
         <odometryFrame>odom</odometryFrame>
         <odometryRate>20.0</odometryRate>
         <robotBaseFrame>base_link</robotBaseFrame>
       </plugin>
     </gazebo>
</robot>
